{
  "threat_severity": "Moderate",
  "public_date": "2020-03-02T00:00:00Z",
  "bugzilla": {
    "description": "CVE-2020-8492 python: wrong backtracking in urllib.request.AbstractBasicAuthHandler allows for a ReDoS",
    "id": "1809065",
    "url": "https://bugzilla.redhat.com/show_bug.cgi?id=1809065"
  },
  "cvss3": {
    "cvss3_base_score": "6.5",
    "cvss3_scoring_vector": "CVSS:3.1/AV:N/AC:L/PR:N/UI:R/S:U/C:N/I:N/A:H",
    "status": "draft"
  },
  "cwe": "CWE-400",
  "details": [
    "Python 2.7 through 2.7.17, 3.5 through 3.5.9, 3.6 through 3.6.10, 3.7 through 3.7.6, and 3.8 through 3.8.1 allows an HTTP server to conduct Regular Expression Denial of Service (ReDoS) attacks against a client because of urllib.request.AbstractBasicAuthHandler catastrophic backtracking."
  ],
  "statement": "Applications that use AbstractBasicAuthHandler, HTTPBasicAuthHandler and ProxyBasicAuthHandler may be affected by this flaw. Other classes may use the vulnerable method http_error_auth_reqed in AbstractBasicAuthHandler as well.\nVersions of python36:3.6/python36 as shipped with Red Hat Enterprise Linux 8 are marked as notaffected as they just provide \"symlinks\" to the main python3 component, which provides the actual interpreter of the Python programming language.",
  "package_state": [
    {
      "product_name": "Red Hat Enterprise Linux 5",
      "fix_state": "Out of support scope",
      "package_name": "python",
      "cpe": "cpe:/o:redhat:enterprise_linux:5"
    },
    {
      "product_name": "Red Hat Enterprise Linux 6",
      "fix_state": "Out of support scope",
      "package_name": "python",
      "cpe": "cpe:/o:redhat:enterprise_linux:6"
    },
    {
      "product_name": "Red Hat Enterprise Linux 7",
      "fix_state": "Will not fix",
      "package_name": "python",
      "cpe": "cpe:/o:redhat:enterprise_linux:7"
    },
    {
      "product_name": "Red Hat Enterprise Linux 7",
      "fix_state": "Affected",
      "package_name": "python3",
      "cpe": "cpe:/o:redhat:enterprise_linux:7"
    },
    {
      "product_name": "Red Hat Enterprise Linux 8",
      "fix_state": "Will not fix",
      "package_name": "python27:2.7/python2",
      "cpe": "cpe:/o:redhat:enterprise_linux:8"
    },
    {
      "product_name": "Red Hat Enterprise Linux 8",
      "fix_state": "Affected",
      "package_name": "python3",
      "cpe": "cpe:/o:redhat:enterprise_linux:8"
    },
    {
      "product_name": "Red Hat Enterprise Linux 8",
      "fix_state": "Not affected",
      "package_name": "python36:3.6/python36",
      "cpe": "cpe:/o:redhat:enterprise_linux:8"
    },
    {
      "product_name": "Red Hat Enterprise Linux 8",
      "fix_state": "Affected",
      "package_name": "python38:3.8/python38",
      "cpe": "cpe:/o:redhat:enterprise_linux:8"
    },
    {
      "product_name": "Red Hat Software Collections",
      "fix_state": "Will not fix",
      "package_name": "python27-python",
      "cpe": "cpe:/a:redhat:rhel_software_collections:3"
    },
    {
      "product_name": "Red Hat Software Collections",
      "fix_state": "Will not fix",
      "package_name": "rh-python36-python",
      "cpe": "cpe:/a:redhat:rhel_software_collections:3"
    },
    {
      "product_name": "Red Hat Software Collections",
      "fix_state": "Affected",
      "package_name": "rh-python38-python",
      "cpe": "cpe:/a:redhat:rhel_software_collections:3"
    }
  ],
  "upstream_fix": "python 3.8.3",
  "name": "CVE-2020-8492"
}
