{
  "threat_severity": "Moderate",
  "public_date": "2019-12-10T00:00:00Z",
  "bugzilla": {
    "description": "CVE-2019-20907 python: infinite loop in the tarfile module via crafted TAR archive",
    "id": "1856481",
    "url": "https://bugzilla.redhat.com/show_bug.cgi?id=1856481"
  },
  "cvss3": {
    "cvss3_base_score": "7.5",
    "cvss3_scoring_vector": "CVSS:3.1/AV:N/AC:L/PR:N/UI:N/S:U/C:N/I:N/A:H",
    "status": "draft"
  },
  "cwe": "CWE-20->CWE-835",
  "details": [
    "In Lib/tarfile.py in Python through 3.8.3, an attacker is able to craft a TAR archive leading to an infinite loop when opened by tarfile.open, because _proc_pax lacks header validation."
  ],
  "statement": "A service is vulnerable if it uses python's tarfile module to open untrusted tar files. If an attacker is able to submit a crafted tar file to a service which uses the tarfile module to open it, an infinite loop will be executed, potentially causing a denial of service. The tarfile module is included with python.",
  "package_state": [
    {
      "product_name": "Red Hat Enterprise Linux 5",
      "fix_state": "Out of support scope",
      "package_name": "python",
      "cpe": "cpe:/o:redhat:enterprise_linux:5"
    },
    {
      "product_name": "Red Hat Enterprise Linux 6",
      "fix_state": "Out of support scope",
      "package_name": "python",
      "cpe": "cpe:/o:redhat:enterprise_linux:6"
    },
    {
      "product_name": "Red Hat Enterprise Linux 7",
      "fix_state": "Affected",
      "package_name": "python",
      "cpe": "cpe:/o:redhat:enterprise_linux:7"
    },
    {
      "product_name": "Red Hat Enterprise Linux 7",
      "fix_state": "Affected",
      "package_name": "python3",
      "cpe": "cpe:/o:redhat:enterprise_linux:7"
    },
    {
      "product_name": "Red Hat Enterprise Linux 8",
      "fix_state": "Affected",
      "package_name": "python27:2.7/python2",
      "cpe": "cpe:/o:redhat:enterprise_linux:8"
    },
    {
      "product_name": "Red Hat Enterprise Linux 8",
      "fix_state": "Affected",
      "package_name": "python3",
      "cpe": "cpe:/o:redhat:enterprise_linux:8"
    },
    {
      "product_name": "Red Hat Enterprise Linux 8",
      "fix_state": "Affected",
      "package_name": "python36:3.6/python36",
      "cpe": "cpe:/o:redhat:enterprise_linux:8"
    },
    {
      "product_name": "Red Hat Enterprise Linux 8",
      "fix_state": "Affected",
      "package_name": "python38:3.8/python38",
      "cpe": "cpe:/o:redhat:enterprise_linux:8"
    },
    {
      "product_name": "Red Hat Quay 3",
      "fix_state": "Affected",
      "package_name": "python27",
      "cpe": "cpe:/a:redhat:quay:3::el7"
    },
    {
      "product_name": "Red Hat Software Collections",
      "fix_state": "Affected",
      "package_name": "python27-python",
      "cpe": "cpe:/a:redhat:rhel_software_collections:3"
    },
    {
      "product_name": "Red Hat Software Collections",
      "fix_state": "Affected",
      "package_name": "rh-python36-python",
      "cpe": "cpe:/a:redhat:rhel_software_collections:3"
    },
    {
      "product_name": "Red Hat Software Collections",
      "fix_state": "Affected",
      "package_name": "rh-python38-python",
      "cpe": "cpe:/a:redhat:rhel_software_collections:3"
    }
  ],
  "name": "CVE-2019-20907",
  "mitigation": {
    "value": "This flaw can be mitigated by not opening untrusted files with tarfile.",
    "lang": "en:us"
  }
}
