{
  "threat_severity": "Moderate",
  "public_date": "2019-11-07T00:00:00Z",
  "bugzilla": {
    "description": "CVE-2019-18874 python-psutil: double free because of refcount mishandling",
    "id": "1772014",
    "url": "https://bugzilla.redhat.com/show_bug.cgi?id=1772014"
  },
  "cvss3": {
    "cvss3_base_score": "7.0",
    "cvss3_scoring_vector": "CVSS:3.0/AV:L/AC:H/PR:N/UI:R/S:U/C:H/I:H/A:H",
    "status": "verified"
  },
  "cwe": "CWE-416",
  "details": [
    "psutil (aka python-psutil) through 5.6.5 can have a double free. This occurs because of refcount mishandling within a while or for loop that converts system data into a Python object.",
    "A double free issue has been discovered in python-psutil because of the mishandling of refcounts while converting system data into Python objects in functions like psutil_disk_partitions(), psutil_users(), psutil_net_if_addrs(), and others. In particular cases, a local attacker may be able to get code execution by manipulating system resources that python-psutil then tries to convert."
  ],
  "acknowledgement": "This issue was discovered by Riccardo Schirone (Red Hat).",
  "affected_release": [
    {
      "product_name": "Red Hat OpenShift Container Platform 4.2",
      "release_date": "2020-07-01T00:00:00Z",
      "advisory": "RHSA-2020:2593",
      "cpe": "cpe:/a:redhat:openshift:4.2::el7",
      "package": "python-psutil-0:5.6.6-1.el7ar"
    },
    {
      "product_name": "Red Hat OpenShift Container Platform 4.3",
      "release_date": "2020-06-23T00:00:00Z",
      "advisory": "RHSA-2020:2635",
      "cpe": "cpe:/a:redhat:openshift:4",
      "package": "python-psutil-0:5.6.6-1.el7ar"
    },
    {
      "product_name": "Red Hat OpenShift Container Platform 4.4",
      "release_date": "2020-06-22T00:00:00Z",
      "advisory": "RHSA-2020:2583",
      "cpe": "cpe:/a:redhat:openshift:4.4::el7",
      "package": "python-psutil-0:5.6.6-1.el7ar"
    }
  ],
  "package_state": [
    {
      "product_name": "Red Hat Enterprise Linux 8",
      "fix_state": "Will not fix",
      "package_name": "python-psutil",
      "cpe": "cpe:/o:redhat:enterprise_linux:8"
    },
    {
      "product_name": "Red Hat OpenStack Platform 10 (Newton)",
      "fix_state": "Will not fix",
      "package_name": "python-psutil",
      "cpe": "cpe:/a:redhat:openstack:10"
    },
    {
      "product_name": "Red Hat OpenStack Platform 13 (Queens)",
      "fix_state": "Will not fix",
      "package_name": "python-psutil",
      "cpe": "cpe:/a:redhat:openstack:13"
    },
    {
      "product_name": "Red Hat OpenStack Platform 14 (Rocky)",
      "fix_state": "Will not fix",
      "package_name": "python-psutil",
      "cpe": "cpe:/a:redhat:openstack:14"
    },
    {
      "product_name": "Red Hat OpenStack Platform 15 (Stein)",
      "fix_state": "Will not fix",
      "package_name": "python-psutil",
      "cpe": "cpe:/a:redhat:openstack:15"
    },
    {
      "product_name": "Red Hat Quay 3",
      "fix_state": "Affected",
      "package_name": "python-psutil",
      "cpe": "cpe:/a:redhat:quay:3::el7"
    },
    {
      "product_name": "Red Hat Satellite 6",
      "fix_state": "Affected",
      "package_name": "python-psutil",
      "cpe": "cpe:/a:redhat:network_satellite:6"
    }
  ],
  "name": "CVE-2019-18874"
}
